<?xml version="1.0"?>
<robot name="edukit_bot">

  <material name="white">
    <color rgba="1 1 1 1"/>
  </material>

  <material name="red">
    <color rgba="1 0 0 1"/>
  </material>

  <link name="base_link">
    <visual>
      <geometry>
        <box size="0.162 0.091 0.03" />
      </geometry>
      <material name="white"/>
    </visual>
  </link>

  <link name="right_wheel">
    <visual>
      <!-- Rotate 90 degrees -->
      <origin rpy="1.57075 0 0" xyz="0 0 0"/>
      <geometry>
        <cylinder length="0.025" radius="0.032"/>
      </geometry>
      <material name="red"/>
    </visual>
  </link>
  <joint name="right_wheel_joint" type="continuous">
    <axis rpy="0 0 0" xyz="0 1 0" />
    <parent link="base_link"/>
    <child link="right_wheel"/>
    <origin rpy="0 0 0" xyz="0.056 0.058 0"/>
  </joint>

  <link name="left_wheel">
    <visual>
      <!-- Rotate 90 degrees -->
      <origin rpy="1.57075 0 0" xyz="0 0 0"/>
      <geometry>
        <cylinder length="0.025" radius="0.032"/>
      </geometry>
      <material name="red"/>
    </visual>
  </link>
  <joint name="left_wheel_joint" type="continuous">
    <axis rpy="0 0 0" xyz="0 1 0" />
    <parent link="base_link"/>
    <child link="left_wheel"/>
    <origin rpy="0 0 0" xyz="0.056 -0.058 0"/>
  </joint>

  <link name="caster">
    <visual>
      <origin rpy="0 0 0" xyz="0 0 0"/>
      <geometry>
        <sphere radius="0.01" />
      </geometry>
      <material name="red"/>
    </visual>
  </link>
  <joint name="caster_joint" type="fixed">
    <parent link="base_link"/>
    <child link="caster"/>
    <origin rpy="0 0 0" xyz="-0.056 0 -0.02"/>
  </joint>
</robot>
